Workbook

Sheet FINANZAS EXPLORADORES DEL REYFC
B1: Finanzas del Destacamento Aguilas de Acero F.C | Q1: INSCRIPCIONES DESTACAMENTO 2026
A2: Fecha | B2: Ingresos | C2: Egresos | D2: Concepto | Q2: Nombre de comandantes | R2: Cancelado
B3: 2250000 | D3: Servicio Social - 90 muchachos | Q3: PASTOR SAMUEL MEJÍA PAYARES | R3: 10000
C4: 40000 | D4: Capacitación para servicio social | Q4: SARA VIRGILIA PATERNINA QUINTANA | R4: 10000
C5: 4000 | D5: Agua | Q5: SARAY BANQUETT GARCIA | R5: 10000
C6: 20000 | D6: Pasajes para Heilen - Servicio social | Q6: YASMIRY ISABEL HERAZO MERCADO | R6: 10000
C7: 5000 | D7: Merienda para Carlos perez | Q7: IBIS LORENA GUTIERREZ JIMENEZ | R7: 10000
C8: 30000 | D8: Cartelera para campamento | Q8: KATERINE GRACE LOPEZ PATERNINA | R8: 10000
C9: 100000 | D9: Materiales de banderines para campamento | Q9: ANGELICA MARIA DE JESUS GIL TORRES | R9: 10000
C10: 150000 | D10: Ofrendas para lideres del servicio social (Evelys,Elizabeth,Maria Victoria) | Q10: MARIA VICTORIA VANEGAS GUTIERREZ | R10: 10000
C11: 50000 | D11: Aporte para auditoria CBI (la luz) | Q11: ESAU ABRAHAM BARRERA ORTEGA | R11: 10000
C12: 400000 | D12: Pasajes para pastores invitados (campamento) | Q12: EDUAR MIGUEL GOMEZ | R12: 10000
C13: 200000 | D13: Anchetas premiación (Campamento) | Q13: EVELIS ASTRID OSORIO CONTRERAS | R13: 10000
C14: 50000 | D14: Globos | Q14: Nombre de exploradores | R14: Cancelado
C15: 400000 | D15: Transportes | Q15: SALVADOR MIRANDA LOPEZ | R15: 8000
C16: 9400 | D16: Cartón industrial para el emblema | Q16: ALLINE CONTRERAS MEJIA | R16: 8000
C17: 420000 | D17: Cuarto pastores | Q17: TIAGO JOSÉ CHALACA AGUIRRE | R17: 8000
C18: 80000 | D18: Espiritu de patrulla | Q18: SAMUEL DAVID CANTERO PEREZ | R18: 8000
C19: 500000 | D19: Ofrendas pastores campamento | Q19: AARON DAVID OVIEDO LOPEZ | R19: 8000
B20: 991050 | D20: Fondos exploradores del rey (ACTIVIDADES) | Q20: ELIAS VILLAMIZAR DE LA HOZ | R20: 8000
C21: 50000 | D21: Fogata (Campamento ) | Q21: AARON DAVID BERMUDES KEY | R21: 8000
C22: 80000 | D22: Certificados Servicio social | Q22: SAMANTHA RAMIREZ PEREZ | R22: 8000
C23: 40000 | D23: Emblema | Q23: MARIPAZ JULIO PATIÑO | R23: 8000
B24: 80000 | D24: Senderismo (Fondo exploradores) | Q24: JUAN LUCAS ORTEGA BANQUET | R24: 8000
C25: 10000 | D25: Agua servicio social | Q25: CELESTE ISABEL OCAMPO QUINTERO | R25: 8000
C26: 50000 | D26: merienda equipo servicio social | Q26: OSTIN NISPERUZA RAMOS | R26: 8000
C27: 30000 | D27: impuestos nequi
C28: 12000 | D28: cartelera clases | Q28: KAROLL SOFIA CHALACA AGUIRRE | R28: 8000
C29: 10000 | D29: moto | Q29: SARA ISABEL PUERTAS PALENCIA | R29: 8000
C30: 19800 | D30: drogas | Q30: SAMARA MIRANDA LOPEZ | R30: 8000
C31: 45700 | D31: materiales didactico | Q31: MAURICIO ALBERTO JULIO PATIÑO | R31: 8000
C32: 80000 | D32: Transporte señor Naudis Montes | Q32: LUIS ALBERTO JULIO PATIÑO | R32: 8000
B33: 90000 | D33: Donaciones de padres exploradores | Q33: ALLEGRA CONTRERAS MEJÍA | R33: 8000
C34: 31400 | D34: remesas para exploradores (campamento ) | Q34: ANDRES RETAMOZA ALFARO | R34: 8000
C35: 48500 | D35: remesas para exploradores (campamento ) | Q35: MIGUEL ARCANGEL ROMERO OLIVA | R35: 8000
C36: 12000 | D36: 20 metros cordon para corbatas | Q36: ISNELLA LUCIA OLIVA OZUNA | R36: 8000
C37: 38000 | D37: clase rotativa Katherine | Q37: CELESTE ISABEL OCAMPO QUINTERO | R37: 8000
C38: 14500 | D38: Brazaletes patrulla de servicio (campamento) | Q38: SANTIAGO VILLAMIZAR DE LA HOZ | R38: 8000
C39: 25000 | D39: Palos para tabú (campamento) | Q39: MARIA ANGEL GOMEZ ROAS | R39: 8000
C40: 14000 | D40: paletas de madera para clases rotativas (campamento) | Q40: KEREN GOMEZ ROAS | R40: 8000
...

Sheet SERVICIO SOCIAL 
A1: FINANZAS SERVICIO SOCIAL
A2: NOMBRE COMPLETO | D2: NUMERO DE CONTACTO | G2: FECHAS DE ABONO | J2: SALDO ABONADO | L2: FECHA DE ABONO | N2: SALDO ABONADO | P2: SALDO ABONADO | R2: TOTAL
R3: =SUM(J3) -> 0
A5: Natasha Rojas Prens | D5: 30148557331 | G5: 46068 | J5: 28000 | R5: =SUM(J5) -> 28000
A7: Manuel David Perez Hernandez | D7: 3215101114 | G7: 46068 | J7: 10000 | R7: =J7 -> 10000
A8: Laura Peralta Cortes | D8: 3104387454 | G8: 46068 | J8: 28000 | R8: =J8 -> 28000
A9: Michell Sofía Nuñez | G9: 46068 | J9: 5000 | R9: =J9+N9 -> 5000
A10: Valeria Isabel Alcalá Pérez | G10: 46068 | J10: 28000 | R10: =J10 -> 28000
A11: Joel Andrés Villalba Sarria | G11: 46068 | J11: 28000 | R11: =J11 -> 28000
A12: Millian David Coude Bedoya | G12: 46068 | J12: 28000 | R12: =J12 -> 28000
A13: Yuliana Andrea Mercado Sierra | G13: 46068 | J13: 15000 | L13: 46082 | N13: 13000 | R13: =SUM(J13+N13) -> 28000
A14: Luis Felipe Pérez Sierra | G14: 46068 | J14: 4000 | L14: 46110 | N14: 5000 | R14: =SUM(J14+N14) -> 9000
A16: Joselyn Michell Sierra Prens | D16: 3042916111 | G16: 46082 | J16: 28000 | R16: =J16 -> 28000
A17: Anderson David Suarez Caballero | D17: 3005170220 | G17: 46082 | J17: 28000 | R17: =J17 -> 28000
A18: Mariana Valentina Tamara Barriento | D18: 3145823676 | G18: 46082 | J18: 28000 | R18: =J18 -> 28000
A19: Ivanna Andrea Orozco Tovar | D19: 3215880065 | G19: 46082 | J19: 28000 | R19: =J19 -> 28000
A20: Angela Lucia Velez Diaz | D20: 3126777308 | G20: 46082 | J20: 28000 | R20: =J20 -> 28000
A21: Zharianella Gomez Guzman | D21: 3229164375 | G21: 46082 | J21: 28000 | R21: =J21 -> 28000
A22: Sharol Dayana Ruiz Agamez | D22: 3182872544 | G22: 46082 | J22: 28000 | R22: =J22 -> 28000
A23: Fernando Andres Campo Mendoza | D23: 3023048765 | G23: 46082 | J23: 28000 | R23: =J23 -> 28000
A24: Juan Diego Artiaga Arrieta | D24: 3245653175 | G24: 46082 | J24: 28000 | R24: =J24 -> 28000
A25: Jhonatan David Guevara Olivero | D25: 3224987230 | G25: 46082 | J25: 3000 | L25: 46103 | N25: 5000 | R25: =J25+N25 -> 8000
A26: Olga Lucia Reyes Romero | D26: 3136061067 | G26: 46082 | J26: 20000 | L26: 46103 | N26: 8000 | R26: =J26+N26 -> 28000
A27: Amy Hernandez Ayaso | D27: 3023166995 | G27: 46096 | J27: 28000 | R27: 28000
A28: Angelica Ripoll Castillo | G28: 46096 | J28: 10000 | R28: =SUM(J28:Q28) -> 10000
A29: Alexander Vergara Suarez | G29: 46096 | J29: 28000 | R29: =SUM(J29:Q29) -> 28000
A30: Daniel Enrique Duran Pelufo | G30: 46096 | J30: 5000 | R30: =SUM(J30:Q30) -> 5000
A31: Isaac David Olivera Osorio | G31: 46096 | J31: 28000 | R31: =SUM(J31:Q31) -> 28000
A32: Camila Jimenez | G32: 46096 | J32: 28000 | R32: =SUM(J32:Q32) -> 28000
A33: Daniela Sofia Rivera Ariza | G33: 46096 | J33: 20000 | L33: 46110 | N33: 8000 | R33: =SUM(J33+N33) -> 28000
A34: Kendry Luz Oliver Martelo | G34: 46103 | J34: 10000 | R34: =SUM(J34:Q34) -> 10000
A35: Dylan José Peralta Arias | G35: 46103 | J35: 5000 | R35: =SUM(J35:Q35) -> 5000
A36: Jhainer Enrique Mendoza Mendoza | G36: 46103 | J36: 10000 | R36: =SUM(J36:Q36) -> 10000
A37: Juan Diego Dominguez Ramos | G37: 46110 | J37: 5000 | R37: =SUM(J37:Q37) -> 5000
A38: Fredy Antonio Lazaro Rosario | G38: 46110 | J38: 10000 | R38: =SUM(J38:Q38) -> 10000
A42: TOTAL INGRESADO | R42: =SUM(R3:S41) -> 675000

Sheet CAMPAMENTO "RAICES" 2026 - EXPL
A1: CAMPAMENTO "RAICES" 2026 | M1: ABONOS A GERIZIM
A2: NOMBRE COMPLETO | C2: FECHA DE ABONO | D2: SALDO ABONADO | E2: FECHA DE ABONO | F2: SALDO ABONADO | G2: FECHA DE ABONO | H2: SALDO ABONADO | I2: FECHA DE ABONO | J2: SALDO ABONADO | K2: TOTAL ABONADO | M2: Fecha | O2: Reporte | Q2: Saldo
A3: AARÓN OVIEDO LOPEZ | C3: 46015 | D3: 40000 | E3: CAMPAMENTO CANCELADO A GERIZIM | K3: =SUM(D3) -> 40000 | M3: 45985 | O3: #VALUE! | Q3: 180000
A4: SAMARA MIRANDA LOPEZ | C4: 46052 | E4: ABONÓ A GERIZIM $110.000 | M4: 46052 | O4: #VALUE! | Q4: 110000
A5: HERMANOS VILLAMIZAR DE LA HOZ | C5: 46053 | D5: 140000 | E5: 46097 | F5: 50000 | K5: =SUM(D5,F5,H5,J5) -> 190000
A6: HERMANOS KEY | C6: 46077 | D6: 15000 | E6: 46110 | F6: 14000 | K6: =SUM(D6,F6,H6,J6) -> 29000
M12: Total | Q12: =SUM(Q3:Q11) -> 290000
A34: TOTAL INGRESADO | K34: =SUM(K3:K33) -> 259000

Sheet CAMPAMENTO "RAICES" 2026 - SERV
A1: CAMPAMENTO "RAICES" 2026
A2: NOMBRE COMPLETO | C2: NUMERO DE CONTACTO | D2: EDAD | E2: COLEGIO | F2: JORNADA | G2: GRADO | H2: FECHA DE ABONO | I2: SALDO ABONADO | J2: FECHA DE ABONO | K2: SALDO ABONADO | L2: FECHA DE ABONO | M2: SALDO ABONADO | N2: FECHA DE ABONO | O2: SALDO ABONADO
A3: Mariangel Contreras Ponnefz | C3: 3104677440 | H3: 46068 | I3: 50000 | P3: =SUM(I3:O3) -> 50000
A4: Talianis García Cochero | C4: 3023714524 | H4: 46068 | I4: 30000 | P4: =SUM(I4:O4) -> 30000
A5: Mariana Molina Paternina | H5: 46068 | I5: 28000 | P5: =SUM(I5:O5) -> 28000
A6: Isabela Pérez Rivera | H6: 46068 | I6: 50000 | P6: =SUM(I6:O6) -> 50000
A7: Jully Andrea Matute Lopez | C7: 3106758524 | D7: 14 | E7: LENIS | F7: MATINAL | G7: 9D | H7: 46082 | I7: 50000 | P7: =SUM(I7:O7) -> 50000
A8: Jose Luis Balza Suarez | C8: 3124204380 | D8: 13 | E8: LENIS | F8: VESPERTINA | G8: 9B | H8: 46082 | I8: 50000 | P8: =SUM(I8:O8) -> 50000
A9: Elias Benavides Tres Palacios | C9: 3014761447 | D9: 13 | E9: LENIS | F9: MATINAL | G9: 9C | H9: 46082 | I9: 28000 | P9: =SUM(I9:O9) -> 28000
A10: Juan Pablo Baquero Salazar | C10: 3023985936 | D10: 14 | E10: LENIS | F10: MATINAL | G10: 9D | H10: 46082 | I10: 30000 | P10: =SUM(I10:O10) -> 30000
A11: Daniela Lucia Mercado Perez | C11: 3128096727 | D11: 14 | E11: LENIS | F11: MATINAL | G11: 9C | H11: 46082 | I11: 20000 | P11: =SUM(I11:O11) -> 20000
A12: Carlos DeJesús Parodi Lorduy | H12: 46068 | I12: 28000 | P12: =SUM(I12:O12) -> 28000
A13: Maria Belen Colon García | C13: 3157440495 | D13: 14 | E13: LENIS | F13: MATINAL | G13: 9D | H13: 46068 | I13: 30000 | J13: 46110 | K13: 50000 | P13: =SUM(I13+K13) -> 80000
A14: Salomé Villalba Calderón | C14: 3226337657 | E14: LENIS | F14: MATINAL | H14: 46104 | I14: 28000 | P14: =SUM(I14:O14) -> 28000
A15: Gabriela Amaya Perez | C15: 3016851621 | D15: 14 | E15: LENIS | F15: MATINAL | G15: 9D | H15: 46105 | I15: 50000 | P15: =SUM(I15:O15) -> 50000
P16: =SUM(I16:O16) -> 0
P17: =SUM(I17:O17) -> 0
P18: =SUM(I18:O18) -> 0
P19: =SUM(I19:O19) -> 0
P20: =SUM(I20:O20) -> 0
P21: =SUM(I21:O21) -> 0
P22: =SUM(I22:O22) -> 0
P23: =SUM(I23:O23) -> 0
P24: =SUM(I24:O24) -> 0
P25: =SUM(I25:O25) -> 0
P26: =SUM(I26:O26) -> 0
P27: =SUM(I27:O27) -> 0
... P33: =SUM(I33:O33) -> 0
A34: TOTAL INGRESADO | P34: =SUM(P3:P33) -> 522000

Sheet SALDOS TOTALES 
C3: CONCEPTO | E3: SALDO
C4: SALDO EXPLORADORES | E4: ='FINANZAS EXPLORADORES DEL REYFC'!D83 -> 852450
C5: INSCRIPCIONES | E5: ='FINANZAS EXPLORADORES DEL REYFC'!T50 -> 102008
C6: CAMPAMENTO "RAICES" 2026 - EXPLORADORES | E6: ='CAMPAMENTO "RAICES" 2026 - EXPL'!K34 -> 259000
C7: CAMPAMENTO "RAICES" 2026 - SERVICIO SOCIAL | E7: ='CAMPAMENTO "RAICES" 2026 - SERV'!P34 -> 522000
C8: SERVICIO SOCIAL | E8: ='SERVICIO SOCIAL '!R42 -> 675000
C10: TOTAL EN EL MINISTERIO | E10: =SUM(E4:F9) -> 2410458
